---
title: JS try catch 与 return 的陷阱
date: 2022-11-04 22:52:49
tags: JavaScript
---

![image.png](https://p9-juejin.byteimg.com/tos-cn-i-k3u1fbpfcp/159802561af04a4d8d3e5f70b83c9afa~tplv-k3u1fbpfcp-watermark.image?)

## 普通 try catch

如下代码输出是？

```js
const foo = () => {
    try {
        console.log(1);
    } catch (error) {
        console.log(2);
    } finally {
        console.log(3);
    }
};

console.log('foo()', foo());
```

执行步骤：

1. 定义函数 foo 变量
2. 执行外层 log
3. 执行 foo 函数
4. 走到 try 输出 1
5. 由于 try 内的代码没有报错，所以不执行
6. 走到 finally 输出 3
7. 最后回到外层 log，输出 undefined

所以输出是：

![image.png](https://p3-juejin.byteimg.com/tos-cn-i-k3u1fbpfcp/02d148e5ff644b2fa3b3cce800f2226e~tplv-k3u1fbpfcp-watermark.image?)

下面增加难度

## try 里面 return

留意注释，标注了代码变更：

```js
const foo = () => {
    try {
        console.log(1);
        return 4; // 新增代码
    } catch (error) {
        console.log(2);
    } finally {
        console.log(3);
    }
};

console.log('foo()', foo());
```

try 里面加了 return，那么 finally 的代码还会执行吗？会的。

![image.png](https://p3-juejin.byteimg.com/tos-cn-i-k3u1fbpfcp/6f43c93d67484e2a8bdef048d44f40bf~tplv-k3u1fbpfcp-watermark.image?)

输出如下：

![image.png](https://p3-juejin.byteimg.com/tos-cn-i-k3u1fbpfcp/17553567633e42b7a988a7bc7b6ba22e~tplv-k3u1fbpfcp-watermark.image?)

即使 try 里面有 return，那么 finally 仍然会执行。

咦，那如果 finally 也有 return 呢？函数就能返回两个值了？

## try 和 finally 都有 return

```js
const foo = () => {
    try {
        console.log(1);
        return 4;
    } catch (error) {
        console.log(2);
    } finally {
        console.log(3);
        return 5; // 新增代码
    }
};

console.log('foo()', foo());
```

finally 的 return 会覆盖掉 try 的 return。

![image.png](https://p3-juejin.byteimg.com/tos-cn-i-k3u1fbpfcp/f6b1c00e995d44fcaea52e403ff8d0a3~tplv-k3u1fbpfcp-watermark.image?)

这代码怎么越来越奇怪了呀，确实，并[不推荐 finally 里写 return](https://eslint.org/docs/latest/rules/no-unsafe-finally)，正常写法应该是你需要 foo 函数的返回值，那么代码正常的话，就应该是在 try 里 return，代码抛出异常的话，就应该在 catch 里 return，finally 应该只做一些 try 和 catch 都做出的时，比如关闭 loading：

```js
const foo = async () => {
    try {
        this.loading = true;
        const data = await fetch('xxx');
        return data.list;
    } catch (error) {
        return [];
    } finally {
        this.loading = false;
    }
};
```

这才是更合理的写法。

![image.png](https://p6-juejin.byteimg.com/tos-cn-i-k3u1fbpfcp/9a43f9c6f5ad4efeaba16a7b22271308~tplv-k3u1fbpfcp-watermark.image?)
